[2024-01-02 21:12:21,733] [citros.citros_obj._save_rendered:269] [ERROR]: "package 'cannon_analytic' not found, searching: ['/opt/ros/humble']"
Traceback (most recent call last):
  File "/opt/ros/humble/lib/python3.10/site-packages/ament_index_python/packages.py", line 58, in get_package_prefix
    content, package_prefix = get_resource('packages', package_name)
  File "/opt/ros/humble/lib/python3.10/site-packages/ament_index_python/resources.py", line 86, in get_resource
    raise LookupError(
LookupError: Could not find the resource 'cannon_analytic' of type 'packages'

During handling of the above exception, another exception occurred:

Traceback (most recent call last):
  File "/home/ros/.local/lib/python3.10/site-packages/citros/parameter_setup.py", line 267, in _save_rendered
    path_to_package = get_package_share_directory(package_name)
  File "/opt/ros/humble/lib/python3.10/site-packages/ament_index_python/packages.py", line 80, in get_package_share_directory
    path = os.path.join(get_package_prefix(package_name), 'share', package_name)
  File "/opt/ros/humble/lib/python3.10/site-packages/ament_index_python/packages.py", line 60, in get_package_prefix
    raise PackageNotFoundError(
ament_index_python.packages.PackageNotFoundError: "package 'cannon_analytic' not found, searching: ['/opt/ros/humble']"
[2024-01-02 21:12:21,739] [citros.citros_obj._save_rendered:269] [ERROR]: "package 'cannon_numeric' not found, searching: ['/opt/ros/humble']"
Traceback (most recent call last):
  File "/opt/ros/humble/lib/python3.10/site-packages/ament_index_python/packages.py", line 58, in get_package_prefix
    content, package_prefix = get_resource('packages', package_name)
  File "/opt/ros/humble/lib/python3.10/site-packages/ament_index_python/resources.py", line 86, in get_resource
    raise LookupError(
LookupError: Could not find the resource 'cannon_numeric' of type 'packages'

During handling of the above exception, another exception occurred:

Traceback (most recent call last):
  File "/home/ros/.local/lib/python3.10/site-packages/citros/parameter_setup.py", line 267, in _save_rendered
    path_to_package = get_package_share_directory(package_name)
  File "/opt/ros/humble/lib/python3.10/site-packages/ament_index_python/packages.py", line 80, in get_package_share_directory
    path = os.path.join(get_package_prefix(package_name), 'share', package_name)
  File "/opt/ros/humble/lib/python3.10/site-packages/ament_index_python/packages.py", line 60, in get_package_prefix
    raise PackageNotFoundError(
ament_index_python.packages.PackageNotFoundError: "package 'cannon_numeric' not found, searching: ['/opt/ros/humble']"
[2024-01-02 21:12:21,740] [citros.citros_obj._save_rendered:269] [ERROR]: "package 'scheduler' not found, searching: ['/opt/ros/humble']"
Traceback (most recent call last):
  File "/opt/ros/humble/lib/python3.10/site-packages/ament_index_python/packages.py", line 58, in get_package_prefix
    content, package_prefix = get_resource('packages', package_name)
  File "/opt/ros/humble/lib/python3.10/site-packages/ament_index_python/resources.py", line 86, in get_resource
    raise LookupError(
LookupError: Could not find the resource 'scheduler' of type 'packages'

During handling of the above exception, another exception occurred:

Traceback (most recent call last):
  File "/home/ros/.local/lib/python3.10/site-packages/citros/parameter_setup.py", line 267, in _save_rendered
    path_to_package = get_package_share_directory(package_name)
  File "/opt/ros/humble/lib/python3.10/site-packages/ament_index_python/packages.py", line 80, in get_package_share_directory
    path = os.path.join(get_package_prefix(package_name), 'share', package_name)
  File "/opt/ros/humble/lib/python3.10/site-packages/ament_index_python/packages.py", line 60, in get_package_prefix
    raise PackageNotFoundError(
ament_index_python.packages.PackageNotFoundError: "package 'scheduler' not found, searching: ['/opt/ros/humble']"
[2024-01-02 21:13:19,783] [citros.citros_obj._save_rendered:269] [ERROR]: "package 'cannon_analytic' not found, searching: ['/opt/ros/humble']"
Traceback (most recent call last):
  File "/opt/ros/humble/lib/python3.10/site-packages/ament_index_python/packages.py", line 58, in get_package_prefix
    content, package_prefix = get_resource('packages', package_name)
  File "/opt/ros/humble/lib/python3.10/site-packages/ament_index_python/resources.py", line 86, in get_resource
    raise LookupError(
LookupError: Could not find the resource 'cannon_analytic' of type 'packages'

During handling of the above exception, another exception occurred:

Traceback (most recent call last):
  File "/home/ros/.local/lib/python3.10/site-packages/citros/parameter_setup.py", line 267, in _save_rendered
    path_to_package = get_package_share_directory(package_name)
  File "/opt/ros/humble/lib/python3.10/site-packages/ament_index_python/packages.py", line 80, in get_package_share_directory
    path = os.path.join(get_package_prefix(package_name), 'share', package_name)
  File "/opt/ros/humble/lib/python3.10/site-packages/ament_index_python/packages.py", line 60, in get_package_prefix
    raise PackageNotFoundError(
ament_index_python.packages.PackageNotFoundError: "package 'cannon_analytic' not found, searching: ['/opt/ros/humble']"
[2024-01-02 21:13:19,788] [citros.citros_obj._save_rendered:269] [ERROR]: "package 'cannon_numeric' not found, searching: ['/opt/ros/humble']"
Traceback (most recent call last):
  File "/opt/ros/humble/lib/python3.10/site-packages/ament_index_python/packages.py", line 58, in get_package_prefix
    content, package_prefix = get_resource('packages', package_name)
  File "/opt/ros/humble/lib/python3.10/site-packages/ament_index_python/resources.py", line 86, in get_resource
    raise LookupError(
LookupError: Could not find the resource 'cannon_numeric' of type 'packages'

During handling of the above exception, another exception occurred:

Traceback (most recent call last):
  File "/home/ros/.local/lib/python3.10/site-packages/citros/parameter_setup.py", line 267, in _save_rendered
    path_to_package = get_package_share_directory(package_name)
  File "/opt/ros/humble/lib/python3.10/site-packages/ament_index_python/packages.py", line 80, in get_package_share_directory
    path = os.path.join(get_package_prefix(package_name), 'share', package_name)
  File "/opt/ros/humble/lib/python3.10/site-packages/ament_index_python/packages.py", line 60, in get_package_prefix
    raise PackageNotFoundError(
ament_index_python.packages.PackageNotFoundError: "package 'cannon_numeric' not found, searching: ['/opt/ros/humble']"
[2024-01-02 21:13:19,789] [citros.citros_obj._save_rendered:269] [ERROR]: "package 'scheduler' not found, searching: ['/opt/ros/humble']"
Traceback (most recent call last):
  File "/opt/ros/humble/lib/python3.10/site-packages/ament_index_python/packages.py", line 58, in get_package_prefix
    content, package_prefix = get_resource('packages', package_name)
  File "/opt/ros/humble/lib/python3.10/site-packages/ament_index_python/resources.py", line 86, in get_resource
    raise LookupError(
LookupError: Could not find the resource 'scheduler' of type 'packages'

During handling of the above exception, another exception occurred:

Traceback (most recent call last):
  File "/home/ros/.local/lib/python3.10/site-packages/citros/parameter_setup.py", line 267, in _save_rendered
    path_to_package = get_package_share_directory(package_name)
  File "/opt/ros/humble/lib/python3.10/site-packages/ament_index_python/packages.py", line 80, in get_package_share_directory
    path = os.path.join(get_package_prefix(package_name), 'share', package_name)
  File "/opt/ros/humble/lib/python3.10/site-packages/ament_index_python/packages.py", line 60, in get_package_prefix
    raise PackageNotFoundError(
ament_index_python.packages.PackageNotFoundError: "package 'scheduler' not found, searching: ['/opt/ros/humble']"
